/home/wqlian/project/miniconda3/envs/TR/lib/python3.6/site-packages/foolbox/attacks/base.py:95: UserWarning: DeepFoolAttack did not find an adversarial, maybe the model or the criterion is not supported by this attack.
  " attack.".format(self.name())
OK
